<?xml version="1.0"?>
<robot name="/memristor/Documents/storebot.urdf" xmlns:xacro="http://ros.org/wiki/xacro">
    <link name="base_link">
        <visual>
            <origin xyz="-0.24 -0.01 -0.14" rpy="0 0 0" />
            <geometry>
                <box size="0.1 0.1 0.2" />
            </geometry>
        </visual>
        <collision>
            <origin xyz="-0.24 -0.01 -0.14" rpy="0 0 0" />
            <geometry>
                <box size="0.1 0.1 0.2" />
            </geometry>
        </collision>
        <visual>
            <origin xyz="0.25 -0.01 -0.14" rpy="0 0 0" />
            <geometry>
                <box size="0.1 0.1 0.2" />
            </geometry>
        </visual>
        <collision>
            <origin xyz="0.25 -0.01 -0.14" rpy="0 0 0" />
            <geometry>
                <box size="0.1 0.1 0.2" />
            </geometry>
        </collision>
        <visual>
            <geometry>
                <box size="0.8 1 0.1" />
            </geometry>
        </visual>
        <collision>
            <geometry>
                <box size="0.8 1 0.1" />
            </geometry>
        </collision>
        <visual>
            <origin xyz="-0.35 0.45 -0.09" rpy="0 0 0" />
            <geometry>
                <box size="0.1 0.1 0.2" />
            </geometry>
        </visual>
        <collision>
            <origin xyz="-0.35 0.45 -0.09" rpy="0 0 0" />
            <geometry>
                <box size="0.1 0.1 0.2" />
            </geometry>
        </collision>
        <visual>
            <origin xyz="-0.35 -0.45 -0.09" rpy="0 0 0" />
            <geometry>
                <box size="0.1 0.1 0.2" />
            </geometry>
        </visual>
        <collision>
            <origin xyz="-0.35 -0.45 -0.09" rpy="0 0 0" />
            <geometry>
                <box size="0.1 0.1 0.2" />
            </geometry>
        </collision>
        <visual>
            <origin xyz="0.35 -0.45 -0.09" rpy="0 0 0" />
            <geometry>
                <box size="0.1 0.1 0.2" />
            </geometry>
        </visual>
        <collision>
            <origin xyz="0.35 -0.45 -0.09" rpy="0 0 0" />
            <geometry>
                <box size="0.1 0.1 0.2" />
            </geometry>
        </collision>
        <visual>
            <origin xyz="0.35 0.45 -0.09" rpy="0 0 0" />
            <geometry>
                <box size="0.1 0.1 0.2" />
            </geometry>
        </visual>
        <collision>
            <origin xyz="0.35 0.45 -0.09" rpy="0 0 0" />
            <geometry>
                <box size="0.1 0.1 0.2" />
            </geometry>
        </collision>
    </link>
    <joint name="CASTER_WHEEL_LF" type="continuous">
        <parent link="base_link" />
        <child link="caster wheel" />
        <axis xyz="0 1 0.000003" />
        <origin xyz="-0.352 0.45 -0.19" rpy="1.570793 0 2.756718" />
    </joint>
    <link name="caster wheel">
        <visual>
            <origin xyz="0.000003 -0.032 0.0029" rpy="1.25 0 0" />
            <geometry>
                <box size="0.05 0.028 0.067" />
            </geometry>
        </visual>
        <collision>
            <origin xyz="0.000003 -0.032 0.0029" rpy="1.25 0 0" />
            <geometry>
                <box size="0.05 0.028 0.067" />
            </geometry>
        </collision>
    </link>
    <joint name="casterWheelRim" type="continuous">
        <parent link="caster wheel" />
        <child link="solid" />
        <axis xyz="1 0 0" />
        <origin xyz="0.000003 -0.052101 0.012643" rpy="0.009041 0 0" />
    </joint>
    <link name="solid">
        <visual>
            <origin xyz="0 0 0" rpy="-1.570796 0 1.5708" />
            <geometry>
                <cylinder radius="0.0375" length="0.025" />
            </geometry>
        </visual>
        <collision>
            <origin xyz="0 0 0" rpy="-1.570796 0 1.5708" />
            <geometry>
                <cylinder radius="0.0375" length="0.025" />
            </geometry>
        </collision>
    </link>
    <joint name="CASTER_WHEEL_RF" type="continuous">
        <parent link="base_link" />
        <child link="caster wheel(1)" />
        <axis xyz="0 1 0" />
        <origin xyz="0.348 0.45 -0.19" rpy="1.570796 0 2.35886" />
    </joint>
    <link name="caster wheel(1)">
        <visual>
            <origin xyz="0 -0.032 0.0029" rpy="1.25 0 0" />
            <geometry>
                <box size="0.05 0.028 0.067" />
            </geometry>
        </visual>
        <collision>
            <origin xyz="0 -0.032 0.0029" rpy="1.25 0 0" />
            <geometry>
                <box size="0.05 0.028 0.067" />
            </geometry>
        </collision>
    </link>
    <joint name="casterWheelRim_0" type="continuous">
        <parent link="caster wheel(1)" />
        <child link="solid_1" />
        <axis xyz="1 0 0" />
        <origin xyz="0 -0.052101 0.012643" rpy="-2.695981 0 0" />
    </joint>
    <link name="solid_1">
        <visual>
            <origin xyz="0 0 0" rpy="-1.570796 0 1.5708" />
            <geometry>
                <cylinder radius="0.0375" length="0.025" />
            </geometry>
        </visual>
        <collision>
            <origin xyz="0 0 0" rpy="-1.570796 0 1.5708" />
            <geometry>
                <cylinder radius="0.0375" length="0.025" />
            </geometry>
        </collision>
    </link>
    <joint name="CASTER_WHEEL_RR" type="continuous">
        <parent link="base_link" />
        <child link="caster wheel(2)" />
        <axis xyz="0 1 0" />
        <origin xyz="0.348 -0.45 -0.19" rpy="1.570796 0 -2.48592" />
    </joint>
    <link name="caster wheel(2)">
        <visual>
            <origin xyz="-0.000001 -0.032 0.0029" rpy="1.25 0 0" />
            <geometry>
                <box size="0.05 0.028 0.067" />
            </geometry>
        </visual>
        <collision>
            <origin xyz="-0.000001 -0.032 0.0029" rpy="1.25 0 0" />
            <geometry>
                <box size="0.05 0.028 0.067" />
            </geometry>
        </collision>
    </link>
    <joint name="casterWheelRim_2" type="continuous">
        <parent link="caster wheel(2)" />
        <child link="solid_3" />
        <axis xyz="1 0 0" />
        <origin xyz="-0.000001 -0.052101 0.012643" rpy="0.754265 0 0" />
    </joint>
    <link name="solid_3">
        <visual>
            <origin xyz="0 0 0" rpy="-1.570796 0 1.5708" />
            <geometry>
                <cylinder radius="0.0375" length="0.025" />
            </geometry>
        </visual>
        <collision>
            <origin xyz="0 0 0" rpy="-1.570796 0 1.5708" />
            <geometry>
                <cylinder radius="0.0375" length="0.025" />
            </geometry>
        </collision>
    </link>
    <joint name="CASTER_WHEEL_LR" type="continuous">
        <parent link="base_link" />
        <child link="caster wheel(3)" />
        <axis xyz="0 1 0" />
        <origin xyz="-0.352 -0.45 -0.19" rpy="1.570796 0 -2.821154" />
    </joint>
    <link name="caster wheel(3)">
        <visual>
            <origin xyz="0 -0.032 0.0029" rpy="1.25 0 0" />
            <geometry>
                <box size="0.05 0.028 0.067" />
            </geometry>
        </visual>
        <collision>
            <origin xyz="0 -0.032 0.0029" rpy="1.25 0 0" />
            <geometry>
                <box size="0.05 0.028 0.067" />
            </geometry>
        </collision>
    </link>
    <joint name="casterWheelRim_4" type="continuous">
        <parent link="caster wheel(3)" />
        <child link="solid_5" />
        <axis xyz="1 0 0" />
        <origin xyz="0 -0.052101 0.012643" rpy="-0.815383 0 0" />
    </joint>
    <link name="solid_5">
        <visual>
            <origin xyz="0 0 0" rpy="-1.570796 0 1.5708" />
            <geometry>
                <cylinder radius="0.0375" length="0.025" />
            </geometry>
        </visual>
        <collision>
            <origin xyz="0 0 0" rpy="-1.570796 0 1.5708" />
            <geometry>
                <cylinder radius="0.0375" length="0.025" />
            </geometry>
        </collision>
    </link>
    <joint name="left_motor" type="continuous">
        <parent link="base_link" />
        <child link="left_wheel" />
        <axis xyz="1 0 0" />
        <limit effort="200" velocity="10" />
        <origin xyz="0.353 0 -0.18" rpy="0.856394 0 0" />
    </joint>
    <link name="left_wheel">
        <visual>
            <origin xyz="0.0001 0 0" rpy="1.570796 0.000001 1.570799" />
            <geometry>
                <cylinder radius="0.11" length="0.095" />
            </geometry>
        </visual>
        <collision>
            <origin xyz="0.0001 0 0" rpy="1.570796 0.000001 1.570799" />
            <geometry>
                <cylinder radius="0.11" length="0.095" />
            </geometry>
        </collision>
    </link>
    <joint name="right_motor" type="continuous">
        <parent link="base_link" />
        <child link="right_wheel" />
        <axis xyz="-1 -0.000003 0" />
        <limit effort="200" velocity="10" />
        <origin xyz="-0.3469 0 -0.18" rpy="-1.001909 -0.000002 3.141591" />
    </joint>
    <link name="right_wheel">
        <visual>
            <origin xyz="-0.0001 0 0" rpy="1.570796 0.000001 1.570799" />
            <geometry>
                <cylinder radius="0.11" length="0.095" />
            </geometry>
        </visual>
        <collision>
            <origin xyz="-0.0001 0 0" rpy="1.570796 0.000001 1.570799" />
            <geometry>
                <cylinder radius="0.11" length="0.095" />
            </geometry>
        </collision>
    </link>
    <link name="lidar">
    </link>
    <joint name="base_link_lidar_joint" type="fixed">
        <parent link="base_link" />
        <child link="lidar" />
        <origin xyz="-0.0001 0 0.12" rpy="0 0 -1.570795" />
    </joint>
    <link name="imu">
    </link>
    <joint name="base_link_imu_joint" type="fixed">
        <parent link="base_link" />
        <child link="imu" />
        <origin xyz="0 0 0" rpy="0 0 0" />
    </joint>

    <webots>
        <plugin type="store_automation.storebot_driver.StorebotDriver" />
    </webots>
</robot>